[2022-08-01 02:02:47,258] {taskinstance.py:1179} INFO - Dependencies all met for <TaskInstance: banco_central_ingestao.importar_arquivos_brutos manual__2022-08-01T02:02:45.822716+00:00 [queued]>
[2022-08-01 02:02:47,273] {taskinstance.py:1179} INFO - Dependencies all met for <TaskInstance: banco_central_ingestao.importar_arquivos_brutos manual__2022-08-01T02:02:45.822716+00:00 [queued]>
[2022-08-01 02:02:47,273] {taskinstance.py:1376} INFO - 
--------------------------------------------------------------------------------
[2022-08-01 02:02:47,274] {taskinstance.py:1377} INFO - Starting attempt 1 of 2
[2022-08-01 02:02:47,274] {taskinstance.py:1378} INFO - 
--------------------------------------------------------------------------------
[2022-08-01 02:02:47,293] {taskinstance.py:1397} INFO - Executing <Task(PythonOperator): importar_arquivos_brutos> on 2022-08-01 02:02:45.822716+00:00
[2022-08-01 02:02:47,301] {standard_task_runner.py:52} INFO - Started process 3334 to run task
[2022-08-01 02:02:47,308] {standard_task_runner.py:79} INFO - Running: ['***', 'tasks', 'run', 'banco_central_ingestao', 'importar_arquivos_brutos', 'manual__2022-08-01T02:02:45.822716+00:00', '--job-id', '16', '--raw', '--subdir', 'DAGS_FOLDER/Teste.py', '--cfg-path', '/tmp/tmpal_lrbel', '--error-file', '/tmp/tmprw6juild']
[2022-08-01 02:02:47,310] {standard_task_runner.py:80} INFO - Job 16: Subtask importar_arquivos_brutos
[2022-08-01 02:02:47,391] {task_command.py:371} INFO - Running <TaskInstance: banco_central_ingestao.importar_arquivos_brutos manual__2022-08-01T02:02:45.822716+00:00 [running]> on host af485ce0d591
[2022-08-01 02:02:47,472] {taskinstance.py:1591} INFO - Exporting the following env vars:
AIRFLOW_CTX_DAG_OWNER=***
AIRFLOW_CTX_DAG_ID=banco_central_ingestao
AIRFLOW_CTX_TASK_ID=importar_arquivos_brutos
AIRFLOW_CTX_EXECUTION_DATE=2022-08-01T02:02:45.822716+00:00
AIRFLOW_CTX_TRY_NUMBER=1
AIRFLOW_CTX_DAG_RUN_ID=manual__2022-08-01T02:02:45.822716+00:00
[2022-08-01 02:02:47,477] {taskinstance.py:1909} ERROR - Task failed with exception
Traceback (most recent call last):
  File "/home/airflow/.local/lib/python3.7/site-packages/airflow/operators/python.py", line 171, in execute
    return_value = self.execute_callable()
  File "/home/airflow/.local/lib/python3.7/site-packages/airflow/operators/python.py", line 189, in execute_callable
    return self.python_callable(*self.op_args, **self.op_kwargs)
  File "/opt/airflow/dags/Teste.py", line 12, in importar_arquivos_brutos
    df_consolidado = pd.read_csv(caminho_raw + '/df_consolidado.csv', encoding='latin1')
  File "/home/airflow/.local/lib/python3.7/site-packages/pandas/util/_decorators.py", line 311, in wrapper
    return func(*args, **kwargs)
  File "/home/airflow/.local/lib/python3.7/site-packages/pandas/io/parsers/readers.py", line 586, in read_csv
    return _read(filepath_or_buffer, kwds)
  File "/home/airflow/.local/lib/python3.7/site-packages/pandas/io/parsers/readers.py", line 482, in _read
    parser = TextFileReader(filepath_or_buffer, **kwds)
  File "/home/airflow/.local/lib/python3.7/site-packages/pandas/io/parsers/readers.py", line 811, in __init__
    self._engine = self._make_engine(self.engine)
  File "/home/airflow/.local/lib/python3.7/site-packages/pandas/io/parsers/readers.py", line 1040, in _make_engine
    return mapping[engine](self.f, **self.options)  # type: ignore[call-arg]
  File "/home/airflow/.local/lib/python3.7/site-packages/pandas/io/parsers/c_parser_wrapper.py", line 51, in __init__
    self._open_handles(src, kwds)
  File "/home/airflow/.local/lib/python3.7/site-packages/pandas/io/parsers/base_parser.py", line 229, in _open_handles
    errors=kwds.get("encoding_errors", "strict"),
  File "/home/airflow/.local/lib/python3.7/site-packages/pandas/io/common.py", line 707, in get_handle
    newline="",
FileNotFoundError: [Errno 2] No such file or directory: '/media/tchaikovsky/DataResearch/mt/air-dbt-ge/data/raw//df_consolidado.csv'
[2022-08-01 02:02:47,487] {taskinstance.py:1420} INFO - Marking task as UP_FOR_RETRY. dag_id=banco_central_ingestao, task_id=importar_arquivos_brutos, execution_date=20220801T020245, start_date=20220801T020247, end_date=20220801T020247
[2022-08-01 02:02:47,500] {standard_task_runner.py:97} ERROR - Failed to execute job 16 for task importar_arquivos_brutos ([Errno 2] No such file or directory: '/media/tchaikovsky/DataResearch/mt/air-dbt-ge/data/raw//df_consolidado.csv'; 3334)
[2022-08-01 02:02:47,521] {local_task_job.py:156} INFO - Task exited with return code 1
[2022-08-01 02:02:47,566] {local_task_job.py:273} INFO - 0 downstream tasks scheduled from follow-on schedule check
